[2023-05-08 09:11:16,989] {taskinstance.py:1179} INFO - Dependencies all met for <TaskInstance: dst_report_dags.get_file_from_gcs manual__2023-05-08T09:11:12.007377+00:00 [queued]>
[2023-05-08 09:11:16,997] {taskinstance.py:1179} INFO - Dependencies all met for <TaskInstance: dst_report_dags.get_file_from_gcs manual__2023-05-08T09:11:12.007377+00:00 [queued]>
[2023-05-08 09:11:17,001] {taskinstance.py:1376} INFO - 
--------------------------------------------------------------------------------
[2023-05-08 09:11:17,002] {taskinstance.py:1377} INFO - Starting attempt 1 of 1
[2023-05-08 09:11:17,002] {taskinstance.py:1378} INFO - 
--------------------------------------------------------------------------------
[2023-05-08 09:11:17,013] {taskinstance.py:1397} INFO - Executing <Task(PythonOperator): get_file_from_gcs> on 2023-05-08 09:11:12.007377+00:00
[2023-05-08 09:11:17,023] {standard_task_runner.py:79} INFO - Running: ['airflow', 'tasks', 'run', 'dst_report_dags', 'get_file_from_gcs', 'manual__2023-05-08T09:11:12.007377+00:00', '--job-id', '58', '--raw', '--subdir', 'DAGS_FOLDER/dst_report_dags.py', '--cfg-path', '/tmp/tmpyo64z400', '--error-file', '/tmp/tmpgfmpv8ty']
[2023-05-08 09:11:17,020] {standard_task_runner.py:52} INFO - Started process 22 to run task
[2023-05-08 09:11:17,025] {standard_task_runner.py:80} INFO - Job 58: Subtask get_file_from_gcs
[2023-05-08 09:11:17,087] {task_command.py:371} INFO - Running <TaskInstance: dst_report_dags.get_file_from_gcs manual__2023-05-08T09:11:12.007377+00:00 [running]> on host dstreportdagsgetfilefromgcs-06c337777cdd476c85eac00f1e3871e8
[2023-05-08 09:11:18,068] {logging_mixin.py:115} WARNING - /home/airflow/.local/lib/python3.8/site-packages/airflow/models/renderedtifields.py:249 SAWarning: Coercing Subquery object into a select() for use in IN(); please pass a select() construct explicitly
[2023-05-08 09:11:18,078] {taskinstance.py:1589} INFO - Exporting the following env vars:
AIRFLOW_CTX_DAG_OWNER=airflow
AIRFLOW_CTX_DAG_ID=dst_report_dags
AIRFLOW_CTX_TASK_ID=get_file_from_gcs
AIRFLOW_CTX_EXECUTION_DATE=2023-05-08T09:11:12.007377+00:00
AIRFLOW_CTX_TRY_NUMBER=1
AIRFLOW_CTX_DAG_RUN_ID=manual__2023-05-08T09:11:12.007377+00:00
[2023-05-08 09:11:19,356] {taskinstance.py:1909} ERROR - Task failed with exception
Traceback (most recent call last):
  File "/home/airflow/.local/lib/python3.8/site-packages/airflow/operators/python.py", line 171, in execute
    return_value = self.execute_callable()
  File "/home/airflow/.local/lib/python3.8/site-packages/airflow/operators/python.py", line 189, in execute_callable
    return self.python_callable(*self.op_args, **self.op_kwargs)
  File "/opt/airflow/dags/dst_report_dags.py", line 41, in get_file_from_gcs
    blob.download_to_filename(f"opt/airflow/{item[17:]}")
  File "/home/airflow/.local/lib/python3.8/site-packages/google/cloud/storage/blob.py", line 1282, in download_to_filename
    with open(filename, "wb") as file_obj:
FileNotFoundError: [Errno 2] No such file or directory: 'opt/airflow/2023-01-31_dst_revenue.csv'
[2023-05-08 09:11:19,375] {taskinstance.py:1415} INFO - Marking task as FAILED. dag_id=dst_report_dags, task_id=get_file_from_gcs, execution_date=20230508T091112, start_date=20230508T091116, end_date=20230508T091119
[2023-05-08 09:11:19,386] {standard_task_runner.py:92} ERROR - Failed to execute job 58 for task get_file_from_gcs ([Errno 2] No such file or directory: 'opt/airflow/2023-01-31_dst_revenue.csv'; 22)
[2023-05-08 09:11:19,433] {local_task_job.py:156} INFO - Task exited with return code 1
[2023-05-08 09:11:19,465] {local_task_job.py:273} INFO - 0 downstream tasks scheduled from follow-on schedule check
