[2023-05-10 09:11:05,266] {taskinstance.py:1179} INFO - Dependencies all met for <TaskInstance: get_attachment_from_dst_gmail.write_to_blob manual__2023-05-10T09:10:54.551379+00:00 [queued]>
[2023-05-10 09:11:05,275] {taskinstance.py:1179} INFO - Dependencies all met for <TaskInstance: get_attachment_from_dst_gmail.write_to_blob manual__2023-05-10T09:10:54.551379+00:00 [queued]>
[2023-05-10 09:11:05,276] {taskinstance.py:1376} INFO - 
--------------------------------------------------------------------------------
[2023-05-10 09:11:05,277] {taskinstance.py:1377} INFO - Starting attempt 1 of 1
[2023-05-10 09:11:05,278] {taskinstance.py:1378} INFO - 
--------------------------------------------------------------------------------
[2023-05-10 09:11:05,288] {taskinstance.py:1397} INFO - Executing <Task(PythonOperator): write_to_blob> on 2023-05-10 09:10:54.551379+00:00
[2023-05-10 09:11:05,291] {standard_task_runner.py:52} INFO - Started process 17 to run task
[2023-05-10 09:11:05,294] {standard_task_runner.py:79} INFO - Running: ['airflow', 'tasks', 'run', 'get_attachment_from_dst_gmail', 'write_to_blob', 'manual__2023-05-10T09:10:54.551379+00:00', '--job-id', '37', '--raw', '--subdir', 'DAGS_FOLDER/get_file_from_gmail.py', '--cfg-path', '/tmp/tmp1hfbyznh', '--error-file', '/tmp/tmpfozajml7']
[2023-05-10 09:11:05,296] {standard_task_runner.py:80} INFO - Job 37: Subtask write_to_blob
[2023-05-10 09:11:05,352] {task_command.py:371} INFO - Running <TaskInstance: get_attachment_from_dst_gmail.write_to_blob manual__2023-05-10T09:10:54.551379+00:00 [running]> on host getattachmentfromdstgmailwrite-9a873782d30b4847a4614d29c2261ce2
[2023-05-10 09:11:06,170] {logging_mixin.py:115} WARNING - /home/airflow/.local/lib/python3.8/site-packages/airflow/models/renderedtifields.py:249 SAWarning: Coercing Subquery object into a select() for use in IN(); please pass a select() construct explicitly
[2023-05-10 09:11:06,179] {taskinstance.py:1589} INFO - Exporting the following env vars:
AIRFLOW_CTX_DAG_OWNER=airflow
AIRFLOW_CTX_DAG_ID=get_attachment_from_dst_gmail
AIRFLOW_CTX_TASK_ID=write_to_blob
AIRFLOW_CTX_EXECUTION_DATE=2023-05-10T09:10:54.551379+00:00
AIRFLOW_CTX_TRY_NUMBER=1
AIRFLOW_CTX_DAG_RUN_ID=manual__2023-05-10T09:10:54.551379+00:00
[2023-05-10 09:11:06,398] {__init__.py:48} WARNING - file_cache is unavailable when using oauth2client >= 4.0.0 or google-auth
Traceback (most recent call last):
  File "/home/airflow/.local/lib/python3.8/site-packages/googleapiclient/discovery_cache/file_cache.py", line 33, in <module>
    from oauth2client.contrib.locked_file import LockedFile
ModuleNotFoundError: No module named 'oauth2client'

During handling of the above exception, another exception occurred:

Traceback (most recent call last):
  File "/home/airflow/.local/lib/python3.8/site-packages/googleapiclient/discovery_cache/file_cache.py", line 37, in <module>
    from oauth2client.locked_file import LockedFile
ModuleNotFoundError: No module named 'oauth2client'

During handling of the above exception, another exception occurred:

Traceback (most recent call last):
  File "/home/airflow/.local/lib/python3.8/site-packages/googleapiclient/discovery_cache/__init__.py", line 44, in autodetect
    from . import file_cache
  File "/home/airflow/.local/lib/python3.8/site-packages/googleapiclient/discovery_cache/file_cache.py", line 40, in <module>
    raise ImportError(
ImportError: file_cache is unavailable when using oauth2client >= 4.0.0 or google-auth
[2023-05-10 09:11:08,404] {python.py:173} INFO - Done. Returned value was: None
[2023-05-10 09:11:08,412] {taskinstance.py:1415} INFO - Marking task as SUCCESS. dag_id=get_attachment_from_dst_gmail, task_id=write_to_blob, execution_date=20230510T091054, start_date=20230510T091105, end_date=20230510T091108
[2023-05-10 09:11:08,465] {local_task_job.py:156} INFO - Task exited with return code 0
[2023-05-10 09:11:08,483] {local_task_job.py:273} INFO - 0 downstream tasks scheduled from follow-on schedule check
