[2023-05-09 20:04:23,048] {taskinstance.py:1179} INFO - Dependencies all met for <TaskInstance: dst_report_dags.generate_report scheduled__2023-05-08T00:00:00+00:00 [queued]>
[2023-05-09 20:04:23,063] {taskinstance.py:1179} INFO - Dependencies all met for <TaskInstance: dst_report_dags.generate_report scheduled__2023-05-08T00:00:00+00:00 [queued]>
[2023-05-09 20:04:23,065] {taskinstance.py:1376} INFO - 
--------------------------------------------------------------------------------
[2023-05-09 20:04:23,066] {taskinstance.py:1377} INFO - Starting attempt 1 of 1
[2023-05-09 20:04:23,069] {taskinstance.py:1378} INFO - 
--------------------------------------------------------------------------------
[2023-05-09 20:04:23,090] {taskinstance.py:1397} INFO - Executing <Task(PythonOperator): generate_report> on 2023-05-08 00:00:00+00:00
[2023-05-09 20:04:23,095] {standard_task_runner.py:52} INFO - Started process 21 to run task
[2023-05-09 20:04:23,104] {standard_task_runner.py:79} INFO - Running: ['airflow', 'tasks', 'run', 'dst_report_dags', 'generate_report', 'scheduled__2023-05-08T00:00:00+00:00', '--job-id', '12', '--raw', '--subdir', 'DAGS_FOLDER/dst_report_dags.py', '--cfg-path', '/tmp/tmppbc67e72', '--error-file', '/tmp/tmp2hnm9emo']
[2023-05-09 20:04:23,107] {standard_task_runner.py:80} INFO - Job 12: Subtask generate_report
[2023-05-09 20:04:23,195] {task_command.py:371} INFO - Running <TaskInstance: dst_report_dags.generate_report scheduled__2023-05-08T00:00:00+00:00 [running]> on host dstreportdagsgeneratereport-d43e425bd20c4b31bb48acb1646649f2
[2023-05-09 20:04:24,371] {logging_mixin.py:115} WARNING - /home/airflow/.local/lib/python3.8/site-packages/airflow/models/renderedtifields.py:249 SAWarning: Coercing Subquery object into a select() for use in IN(); please pass a select() construct explicitly
[2023-05-09 20:04:24,384] {taskinstance.py:1589} INFO - Exporting the following env vars:
AIRFLOW_CTX_DAG_OWNER=airflow
AIRFLOW_CTX_DAG_ID=dst_report_dags
AIRFLOW_CTX_TASK_ID=generate_report
AIRFLOW_CTX_EXECUTION_DATE=2023-05-08T00:00:00+00:00
AIRFLOW_CTX_TRY_NUMBER=1
AIRFLOW_CTX_DAG_RUN_ID=scheduled__2023-05-08T00:00:00+00:00
[2023-05-09 20:04:24,386] {taskinstance.py:1909} ERROR - Task failed with exception
Traceback (most recent call last):
  File "/home/airflow/.local/lib/python3.8/site-packages/airflow/operators/python.py", line 171, in execute
    return_value = self.execute_callable()
  File "/home/airflow/.local/lib/python3.8/site-packages/airflow/operators/python.py", line 189, in execute_callable
    return self.python_callable(*self.op_args, **self.op_kwargs)
  File "/opt/airflow/dags/dst_report_dags.py", line 79, in join_csv
    df_report = pd.concat(map(pd.read_csv, files), ignore_index=True)
  File "/home/airflow/.local/lib/python3.8/site-packages/pandas/util/_decorators.py", line 311, in wrapper
    return func(*args, **kwargs)
  File "/home/airflow/.local/lib/python3.8/site-packages/pandas/core/reshape/concat.py", line 347, in concat
    op = _Concatenator(
  File "/home/airflow/.local/lib/python3.8/site-packages/pandas/core/reshape/concat.py", line 404, in __init__
    raise ValueError("No objects to concatenate")
ValueError: No objects to concatenate
[2023-05-09 20:04:24,396] {taskinstance.py:1415} INFO - Marking task as FAILED. dag_id=dst_report_dags, task_id=generate_report, execution_date=20230508T000000, start_date=20230509T200423, end_date=20230509T200424
[2023-05-09 20:04:24,411] {standard_task_runner.py:92} ERROR - Failed to execute job 12 for task generate_report (No objects to concatenate; 21)
[2023-05-09 20:04:24,443] {local_task_job.py:156} INFO - Task exited with return code 1
[2023-05-09 20:04:24,471] {local_task_job.py:273} INFO - 0 downstream tasks scheduled from follow-on schedule check
